<!DOCTYPE html>
<html lang="en">
<head>
    <meta charset="UTF-8">
    <meta http-equiv="X-UA-Compatible" content="IE=edge">
    <meta name="viewport" content="width=device-width, initial-scale=1.0">
    <link rel="preconnect" href="https://fonts.gstatic.com">
    <link href="https://fonts.googleapis.com/css2?family=Roboto:ital,wght@0,300;0,400;0,700;1,300;1,400;1,700&display=swap" rel="stylesheet">
    <link rel="stylesheet" href="../../../../css/style.min.css" />
    <title>Questions and answers</title>
    <script defer src="../../../../js/all.min.js"></script>
</head>
<body>
    <section class="questions-block">
        <div class="qa-box">
            <div class="qa-box__question-box">
                <h2 class="qa-box__question">Что такое callback-функция?</h2>
            </div>
            <div class="qa-box__answer-box">
                <p class="qa-box__answer">Это функция, которая будет вызвана по завершению асинхронного действия.</p>
                <pre>
                    <code>
function loadScript(src, callback) {
    let script = document.createElement('script');
    script.src = src;
    script.onload = () => callback(script);
    document.head.append(script);
}

loadScript('https://cdnjs.cloudflare.com/ajax/libs/lodash.js/3.2.0/lodash.js', script => {
alert(`Здорово, скрипт ${script.src} загрузился`);
alert( _ ); // функция, объявленная в загруженном скрипте
});
                    </code>
                </pre>
                <p class="qa-box__answer">Callback-функция вызывается тогда, когда наступит событие onload(ресурс будет загружен). При этом весь остальной код продолжает выполняться, он не блокируется. Такое написание называют асинхронным программированием с использованием колбэков.</p>
            </div>
        </div>
        <div class="qa-box">
            <div class="qa-box__question-box">
                <h2 class="qa-box__question">Поясните концепцию "перехвата ошибок" в Callback-функцияч?</h2>
            </div>
            <div class="qa-box__answer-box">
                <p class="qa-box__answer">Мы должын предусмотреть два варианта выполнения асинхронного действия: успешное выполнение и ошибка. В зависимости о этого вызывается callback-функция с соответствующими параметрами. Сама callback-функция должна реагировать по зазному при вызове с ошибкой и вызове без нее.</p>
                <pre>
                    <code>
function loadScript(src, callback) {
    let script = document.createElement('script');
    script.src = src;
    
    script.onload = () => callback(null, script);
    script.onerror = () => callback(new Error(`Не удалось загрузить скрипт ${src}`));
    
    document.head.append(script);
}


loadScript('/my/script.js', function(error, script) {
    if (error) {
      // обрабатываем ошибку
    } else {
      // скрипт успешно загружен
    }
});
                    </code>
                </pre>
                <p class="qa-box__answer">Что происходит при вызове функции loadScript:
                    <ul>
                        <li>Передаем callback-функцию с обязательным первым параметром error</li>
                        <li>В теле callback-функции проверяем, был ли передан первый параметр-ошибка или нет. В зависимости от этого выполняем соответствующий блок кода.</li>
                        <li>В самой функции loadScript в зависимости от результата асинхронного действия смотрим, как вызывать callback-функцию - с реальным значением аргумента error или присваеваем ему null.</li>
                    </ul>
                </p>
            </div>
        </div>
        <div class="qa-box">
            <div class="qa-box__question-box">
                <h2 class="qa-box__question">Расскажите, что такое "адская пирамида вызовов"?</h2>
            </div>
            <div class="qa-box__answer-box">
                <p class="qa-box__answer">Это ситуация, при которой результат асинхронного действия вызывается callback-функция, которая в свою очередь также принимает callback-функцию, вызываемую в результате асинхронного действия. И такая вложенность может быть нескольких уровней. Такой код становится трудночитаемый и его сложно поддерживать.</p>
                <pre>
                    <code>
loadScript('1.js', function(error, script) {

    if (error) {
        handleError(error);
    } else {
        // ...
        loadScript('2.js', function(error, script) {
            if (error) {
                handleError(error);
            } else {
                // ...
                loadScript('3.js', function(error, script) {
                    if (error) {
                        handleError(error);
                    } else {
                        // ...и так далее, пока все скрипты не будут загружены (*)
                    }
                });
        
            }
        })
    }
});
                    </code>
                </pre>
                <p class="qa-box__answer">Мы можем попытаться решить эту проблему, изолируя каждое действие в отдельную функцию, вот так:</p>
                <pre>
                    <code>
loadScript('1.js', step1);

function step1(error, script) {
    if (error) {
    handleError(error);
    } else {
    // ...
    loadScript('2.js', step2);
    }
}

function step2(error, script) {
    if (error) {
    handleError(error);
    } else {
    // ...
    loadScript('3.js', step3);
    }
}

function step3(error, script) {
    if (error) {
    handleError(error);
    } else {
    // ...и так далее, пока все скрипты не будут загружены (*)
    }
};
                    </code>
                </pre>
                <p class="qa-box__answer">Эдесь вложенность отсутствует, но такой код кажется разорванным на куски и он трудночитаемый.</p>
            </div>
        </div>
        <div class="qa-box">
            <div class="qa-box__question-box">
                <h2 class="qa-box__question">Каким типом данных является promise? Как его можно создать?</h2>
            </div>
            <div class="qa-box__answer-box">
                <p class="qa-box__answer">Promise - это объект. Создается он при помощи конструктора new Promise(). Конструктор принимает функцию-испольнителя (executor), которая в свою очередь принимает две callback-функции: resolve и reject.</p>
                <pre>
                    <code>
let promise = new Promise(function(resolve, reject) {
    // функция-исполнитель (executor)
});
                    </code>
                </pre>
                <p class="qa-box__answer">Функция executor запускается автоматически в момент создания промиса.</p>
            </div>
        </div>
        <div class="qa-box">
            <div class="qa-box__question-box">
                <h2 class="qa-box__question">Расскажите, как работает промис?</h2>
            </div>
            <div class="qa-box__answer-box">
                <p class="qa-box__answer">Конструктор new Promise() возвращает объект promise и автоматически запускает функцию executor. Функция-испольнитель в зависимости от результата может вызвать либо resolve(value) при успехе, либо reject(error) при ошибке. Сам объект promise при создании имеет два внутренних свойства: state: 'pending' и result: 'undefined'. При успехе свойства меняются на state: 'fulfilled' и result: value. При неудачи свойства меняются на state: 'rejected' и resulst: error</p>
                <p class="qa-box__answer">Обратите внимание, что в фунеции executor может быть вызыван только один колбек, либо resolve, либо reject. Если какой то один уже был вызван, то другой не запустится.</p>
            </div>
        </div>
        <div class="qa-box">
            <div class="qa-box__question-box">
                <h2 class="qa-box__question">Расскажите, что такое then(), catch(), finally() и как они относятся к прописам?</h2>
            </div>
            <div class="qa-box__answer-box">
                <p class="qa-box__answer">Это все методы объекта promise. Самый фундаментальный из них - это then(), он позволяет связывать функцию-испольнитель и функцию-потребитель. Вот его синтаксис:</p>
                <pre>
                    <code>
promise.then(
    function(result) { /* обработает успешное выполнение */ },
    function(error) { /* обработает ошибку */ }
);
                    </code>
                </pre>
                <p class="qa-box__answer">Первая функция в качестве аргумента получает значение value, вторая значение error. В данный метод не обязательно передавать две функции, если нужно обрабатывать только успешное завершение функции-испольнителя.</p>
                <pre>
                    <code>
let promise = new Promise(resolve => {
    setTimeout(() => resolve("done!"), 1000);
});

promise.then(alert); // выведет "done!" спустя одну секунду
                    </code>
                </pre>
                <p class="qa-box__answer">Если мы хотим, чтобы метод then() обрабатывал только завершение с ошибкой, тогда в качестве первого аргумента нужно передать значение null. Объект promise также имеет встроенный метод cathc(), который принимает в аргументе функцию, вызываемую при неудачном завршении функции-испольнителя. В качестве аргумента данная функция принимает объект-ошибку.</p>
                <pre>
                    <code>
let promise = new Promise((resolve, reject) => {
    setTimeout(() => reject(new Error("Ошибка!")), 1000);
});

// .catch(f) это тоже самое, что promise.then(null, f)
promise.catch(alert); // выведет "Error: Ошибка!" спустя одну секунду
                    </code>
                </pre>
                <p class="qa-box__answer">Вызов .catch(f) – это сокращённый, «укороченный» вариант .then(null, f).</p>
                <p class="qa-box__answer">Метод finally() запускается всегда, вне зависимости от результата выполнения функции-испонителя. Важно отметить, что если после данного метода в цепочке вызовов есить либо then() либо cathc(), то они будут вызваны и обработаны. Функция, которая передается в метод finally() не получает аргументов.</p>
                <pre>
                    <code>
new Promise((resolve, reject) => {
    /* сделать что-то, что займёт время, и после вызвать resolve/reject */
})
// выполнится, когда промис завершится, независимо от того, успешно или нет
.finally(() => остановить индикатор загрузки)
.then(result => показать результат, err => показать ошибку)
                    </code>
                </pre>
                <p class="qa-box__answer">Обратите внимание, с какими аргументыми вызывается метод then().</p>
            </div>
        </div>
        <div class="qa-box">
            <div class="qa-box__question-box">
                <h2 class="qa-box__question">Что возвращает метод then()?</h2>
            </div>
            <div class="qa-box__answer-box">
                <p class="qa-box__answer">Метод then() возвращает объект-промис. У нового объекта также можно вызвать метод then(). Таким образом можно выстроить цепочку промисов. Значение, которое возвращается из функции-обработчика, становится результатом выполнения соответствующего промиса и передается в следующий then().</p>
                <pre>
                    <code>
let promise = new Promise(function(resolve, reject) {
    setTimeout(() => resolve(1), 1000);
});

promise.then(function(result) {
    alert(result); // 1
    return result * 2;
});

promise.then(function(result) {
    alert(result); // 1
    return result * 2;
});

promise.then(function(result) {
    alert(result); // 1
    return result * 2;
});
                    </code>
                </pre>
                <p class="qa-box__answer">После каждого вызова обработчика, возвращается новый промис с новым значением value, которое и передается в следующий вызов then(). </p>
            </div>
        </div>
        <div class="qa-box">
            <div class="qa-box__question-box">
                <h2 class="qa-box__question">Расскажите, что происходит, когда функции-обработчик возвращает промис?</h2>
            </div>
            <div class="qa-box__answer-box">
                <p class="qa-box__answer">В этом случае следующий вызов метода then() будет дожедаться завершения промиса и получения его результата и только тогда запустится then().</p>
                <p class="qa-box__answer">Промис запускает метод then() только в том случае, когда state: fulfilled, только тогда функции-обработчику передается результат промиса.</p>
                <p class="qa-box__answer">В случае, когда функция-обработчик возвращает промис, некоторое время его скрытое свойство state: pending, а следовательно следующий then() быть вызван не может. Необходимо ждать, когда state приметь новое значение и свойство result примет свое значение.</p>
                <p class="qa-box__answer">Когда функция-обработчик возвращает другое значение (не промис), то свойства state и result принимают сразу значения, а следовательно сразу возвращается завершенный промис и может вызывать его метод then()</p>
                <pre>
                    <code>
new Promise(function(resolve, reject) {

    setTimeout(() => resolve(1), 1000);
    
}).then(function(result) {

    alert(result); // 1

    return new Promise((resolve, reject) => { // (*)
        setTimeout(() => resolve(result * 2), 1000);
    });

}).then(function(result) { // (**)

    alert(result); // 2

    return new Promise((resolve, reject) => {
        setTimeout(() => resolve(result * 2), 1000);
    });

}).then(function(result) {

    alert(result); // 4

});
                    </code>
                </pre>
                <p class="qa-box__answer">Вероятнее всего, метод then() возвращает обсолютно новый промис.</p>
            </div>
        </div>
        <div class="qa-box">
            <div class="qa-box__question-box">
                <h2 class="qa-box__question">Что будет, если из функции-обработчика вернут объект с методом then()?</h2>
            </div>
            <div class="qa-box__answer-box">
                <p class="qa-box__answer">Такие объекты называются thenable. JS проверяет, есть ли у объекта метод then, и если есть, то он сразу вызывается. Данный метод может получать как аргументы две встроенные функции resolve и reject, которые можно вызывать в теле функции. После вызова одной из этих встроенных функций возвращенный промис заканчивается либо успехом, либо ошибкой (работают также, как и в обычном промисе).</p>
                <pre>
                    <code>
let promise = new Promise((res, rej)=>setTimeout(()=>{res(15)}, 2000))
.then(()=>{
    return{num: 20, then(resolve){resolve(this.num+20)}}
);
                    </code>
                </pre>
                <p class="qa-box__answer">Через 2 минуты вернется созданный промис с resoult:15. Затем запустится его метод then. Поскольку функция обработчик возвращает объект, JS проверяет, есть ли метод then у этого объекта. И так как он есть, то сразу запускает его, передав в качестве аргумента функцию resolve. В теле метода then функция resolve вызывается, она и обновляет состояние псевдообъекта, который и возвращается.</p>
            </div>
        </div>
        <div class="qa-box">
            <div class="qa-box__question-box">
                <h2 class="qa-box__question">Как происходит обработка ошибок в цепочке промисов?</h2>
            </div>
            <div class="qa-box__answer-box">
                <p class="qa-box__answer">Ошибка отлавливается в самом ближайшем методе catch(). Метод catch() может быть не сразу после ошибки, он может быть через несколько методов then() или вообще в самом конце цепочки.</p>
                <pre>
                    <code>
fetch('https://no-such-server.blabla') // ошибка
.then(response => response.json())
.catch(err => alert(err)) // TypeError: failed to fetch (текст может отличаться)
                    </code>
                </pre>
            </div>
        </div>
        <div class="qa-box">
            <div class="qa-box__question-box">
                <h2 class="qa-box__question">Что будет, если произойдет исключение в функции-исполнителе либо функции-обработчеке?</h2>
            </div>
            <div class="qa-box__answer-box">
                <p class="qa-box__answer">В этом случае ошибка все равно будет поймана методом catch(), даже если мы явно не отлоняли промис. Он будет откланен неявно.</p>
                <pre>
                    <code>
new Promise((resolve, reject) => {
    reject(new Error("Ошибка!"));
}).catch(alert); // Error: Ошибка!
                    </code>
                </pre>
                <p class="qa-box__answer">Так отклоняем промис явно.</p>
                <pre>
                    <code>
new Promise((resolve, reject) => {
    throw new Error("Ошибка!");
}).catch(alert); // Error: Ошибка!
                    </code>
                </pre>
                <p class="qa-box__answer">Здесь ошибка генерируется в теле функции-исполнителе, но она все равно поймана методом catch() в цепочке промисов.</p>
                <pre>
                    <code>
new Promise((resolve, reject) => {
    resolve("ок");
}).then((result) => {
    throw new Error("Ошибка!"); // генерируем ошибку
}).catch(alert); // Error: Ошибка!
                    </code>
                </pre>
                <p class="qa-box__answer">Здесь ошибка генерируется в теле функции-обработчике, но она все равно поймана методом catch() в цепочке промисов. Отлавливаются не только генерируемые ошибки, но и системные.</p>
            </div>

        </div>
        <div class="qa-box">
            <div class="qa-box__question-box">
                <h2 class="qa-box__question">Что происходит, когда метод catch() в цепочке промисов ловит ошибку? Что такое пробрасывание ошибок?</h2>
            </div>
            <div class="qa-box__answer-box">
                <p class="qa-box__answer">Когда метод catch() ловит и обрабатывает ошибку, он передает промис дальше по цепочке(для выполнения then()). Если же функция-обработчик в catch() генерирует новую ошибку, то все последующие then() не выполняются, а ошибка передается следующему catch() поцепочке.</p>
                <pre>
                    <code>
new Promise((resolve, reject) => {

    throw new Error("Ошибка!");
    
}).catch(function(error) {
    
    alert("Ошибка обработана, продолжить работу");
    
}).then(() => alert("Управление перейдёт в следующий then"));
                    </code>
                </pre>
                <p class="qa-box__answer">Мы видем, что ошибка обработана и выполняется следующий then().</p>
                <pre>
                    <code>
new Promise((resolve, reject) => {

    throw new Error("Ошибка!");
    
}).catch(function(error) { // (*)
    
    if (error instanceof URIError) {
        // обрабатываем ошибку
    } else {
        alert("Не могу обработать ошибку");
    
        throw error; // пробрасывает эту или другую ошибку в следующий catch
    }
    
}).then(function() {
    /* не выполнится */
}).catch(error => { // (**)
    
    alert(`Неизвестная ошибка: ${error}`);
    // ничего не возвращаем => выполнение продолжается в нормальном режиме
    
});
                    </code>
                </pre>
                <p class="qa-box__answer">Здесь мы видим, что ошибка славливается первым catch() по цепочке, но необрабатывается им, а пробрасывается дальше до следующего catch(). При этом, все идущие между ними then() не выполняются.</p>
            </div>
        </div>
        <div class="qa-box">
            <div class="qa-box__question-box">
                <h2 class="qa-box__question">Что произойдет, если ошибка в промисе не будет отловлена при помощи catch()?</h2>
            </div>
            <div class="qa-box__answer-box">
                <p class="qa-box__answer">Если даже нет конструкции try..catch, то наступит глобальное событие unhandledrejection</p>
                <pre>
                    <code>
window.addEventListener('unhandledrejection', function(event) {
    // объект события имеет два специальных свойства:
    alert(event.promise); // [object Promise] - промис, который сгенерировал ошибку
    alert(event.reason); // Error: Ошибка! - объект ошибки, которая не была обработана
});

new Promise(function() {
throw new Error("Ошибка!");
}); // нет обработчика ошибок
                    </code>
                </pre>
                <p class="qa-box__answer">Если происходит ошибка, и отсутствует её обработчик, то генерируется событие unhandledrejection, и соответствующий объект event содержит информацию об ошибке.</p>
            </div>
        </div>
        <div class="qa-box">
            <div class="qa-box__question-box">
                <h2 class="qa-box__question">Для чего нужен встроенный метод Promise.all()?</h2>
            </div>
            <div class="qa-box__answer-box">
                <p class="qa-box__answer">Данный метод позволяет запустить несколько промисов параллельно и дождаться, когда все они выполнятся.</p>
                <pre>
                    <code>
Promise.all([
    new Promise(resolve => setTimeout(() => resolve(1), 3000)), // 1
    new Promise(resolve => setTimeout(() => resolve(2), 2000)), // 2
    new Promise(resolve => setTimeout(() => resolve(3), 1000))  // 3
]).then(alert); // когда все промисы выполнятся, результат будет 1,2,3
// каждый промис даёт элемент массива
                    </code>
                </pre>
                <p class="qa-box__answer">Результатом выполнения метода будет новый промис с значение result равным массиву результатов всех переданных промисов, причем очередность элементов будет совпадать очереди переданных прописов. Если в каком нибудь из них ошибка, то новый промис будет иметь результат error. Стоти отметить, что если возникает ошибка, то выполнение метода сразу же завершается. В данный метод можно передавать не массив, а любой перебираемый объект.</p>
            </div>
        </div>
        <div class="qa-box">
            <div class="qa-box__question-box">
                <h2 class="qa-box__question">Что делает метод Promise.allSettled() и чем он отличается от Promise.all()?</h2>
            </div>
            <div class="qa-box__answer-box">
                <p class="qa-box__answer">Метод Promise.allSettled() принимает массив промисов и возвращает промис, также как и метод Promise.all(). Однако, если промис, возвращенный методом Promise.all(), имеет в value массив результатов выполнения переданных промисов как [value1, value2, ...], то метод Promise.allSettled() возвращает промис, результатом которого будет массив объектов, формата [{status: 'fulfilled', value: 'one'}, {{status: 'fulfilled', value: 'two'}, {status: rejected, reason: error}, ...]. Как видим, ошибка в каком нибудь одном переданном промисе не вызывает мето catch().</p>
                <pre>
                    <code>
[
    {status: 'fulfilled', value: ...объект ответа...},
    {status: 'fulfilled', value: ...объект ответа...},
    {status: 'rejected', reason: ...объект ошибки...}
]
                    </code>
                </pre>
                <p class="qa-box__answer">Именно такого формата будет результа вызова метода. Стоит отметить, что возвращаемый промис будет дожидаться результат выполнения всех переданных в массиве промисов, и только тогда возвращаемый им промис даст результат. Этот метод появился совсем недавно и для корректоной работы в старых браузерах нужен полифилл.</p>
            </div>
        </div>
        <div class="qa-box">
            <div class="qa-box__question-box">
                <h2 class="qa-box__question">Расскажите принцип работы метода Promise.rise()?</h2>
            </div>
            <div class="qa-box__answer-box">
                <p class="qa-box__answer">Данный метод похож на Promise.all(), но он ожидает завершения не всех переданных промисов, а самого первого. Соответвенно, его и возвращает.</p>
                <pre>
                    <code>
Promise.race([
    new Promise((resolve, reject) => setTimeout(() => resolve(1), 1000)),
    new Promise((resolve, reject) => setTimeout(() => reject(new Error("Ошибка!")), 2000)),
    new Promise((resolve, reject) => setTimeout(() => resolve(3), 3000))
]).then(alert); // 1
                    </code>
                </pre>
                <p class="qa-box__answer">В итоге мы получаем промис с состоянием, которое зависит от первого вызванного метода resolve/reject.</p>
            </div>
        </div>
        <div class="qa-box">
            <div class="qa-box__question-box">
                <h2 class="qa-box__question">Что делают методы Promise.resolve() и Promise.reject()?</h2>
            </div>
            <div class="qa-box__answer-box">
                <p class="qa-box__answer">Promise.resolve(value) создаёт успешно выполненный промис с результатом value.</p>
                <p class="qa-box__answer">Promise.reject(error) создаёт промис, завершённый с ошибкой error.</p>
                <pre>
                    <code>
let promise = new Promise(resolve => resolve(value));

let promise = new Promise((resolve, reject) => reject(error));
                    </code>
                </pre>
                <p class="qa-box__answer">Примеры, показанные в коде, делают тоже самое.</p>
                <p class="qa-box__answer">На практикте данные методы используются редко.</p>
            </div>
        </div>
        <div class="qa-box">
            <div class="qa-box__question-box">
                <h2 class="qa-box__question">Что делает ключевое слово async?</h2>
            </div>
            <div class="qa-box__answer-box">
                <p class="qa-box__answer">Ключевое слово async ставится перед функцией, в результате чего она возвращает промис. Результат выполнения промиса равен том, что возвращает данная функция.</p>
                <pre>
                    <code>
async function f() {
    return 1;
}

f().then(alert); // 1
                    </code>
                </pre>
                <p class="qa-box__answer">Можно вернуть промис из такой функции явно, результат от этого не изменится.</p>
                <pre>
                    <code>
async function f() {
    return Promise.resolve(1);
}

f().then(alert); // 1
                    </code>
                </pre>
            </div>
        </div>
        <div class="qa-box">
            <div class="qa-box__question-box">
                <h2 class="qa-box__question">Что делает ключевое слово await?</h2>
            </div>
            <div class="qa-box__answer-box">
                <p class="qa-box__answer">Ключевое слово await заставит интерпретатор JavaScript ждать до тех пор, пока промис справа от await не выполнится. После чего оно вернёт его результат, и выполнение кода продолжится.</p>
                <pre>
                    <code>
async function f() {

    let promise = new Promise((resolve, reject) => {
        setTimeout(() => resolve("готово!"), 1000)
    });
    
    let result = await promise; // будет ждать, пока промис не выполнится (*)
     
    alert(result); // "готово!"
}
    
f();
                    </code>
                </pre>
            </div>
        </div>
        <div class="qa-box">
            <div class="qa-box__question-box">
                <h2 class="qa-box__question">Можно ли при помощи async/await задать асинхронный метод класса?</h2>
            </div>
            <div class="qa-box__answer-box">
                <p class="qa-box__answer">Да. В этом случае метод будт возвращать промис.</p>
                <pre>
                    <code>
class Waiter {
    async wait() {
        return await Promise.resolve(1);
    }
}

new Waiter()
    .wait()
    .then(alert); // 1
                    </code>
                </pre>
            </div>
        </div>
        <div class="qa-box">
            <div class="qa-box__question-box">
                <h2 class="qa-box__question">Как происходит обработка ошибок?</h2>
            </div>
            <div class="qa-box__answer-box">
                <p class="qa-box__answer">Когда промис завершается успешно, await promise возвращает результат. Когда завершается с ошибкой – будет выброшено исключение. Как если бы на этом месте находилось выражение throw</p>
                <pre>
                    <code>
async function f() {
    await Promise.reject(new Error("Упс!"));
}

//тоже самое, что и:

async function f() {
    throw new Error("Упс!");
}
                    </code>
                </pre>
                <p class="qa-box__answer">На практике промис может завершиться с ошибкой не сразу, а через некоторое время. В этом случае будет задержка, а затем await выбросит исключение. Такие ошибки можно ловить, используя try..catch, как с обычным throw:</p>
                <pre>
                    <code>
async function f() {

    try {
        let response = await fetch('/no-user-here');
        let user = await response.json();
    } catch(err) {
        // перехватит любую ошибку в блоке try: и в fetch, и в response.json
        alert(err);
    }
}

f();
                    </code>
                </pre>
                <p class="qa-box__answer">Если у нас нет try..catch, асинхронная функция будет возвращать завершившийся с ошибкой промис (в состоянии rejected). В этом случае мы можем использовать метод .catch промиса, чтобы обработать ошибку:</p>
                <pre>
                    <code>
async function f() {
    let response = await fetch('http://no-such-url');
}

// f() вернёт промис в состоянии rejected
f().catch(alert); // TypeError: failed to fetch // (*)
                    </code>
                </pre>
            </div>
        </div>
    </section>
</body>
</html>

<div class="qa-box">
    <div class="qa-box__question-box">
        <h2 class="qa-box__question">Объясните, что такое "частичное применение"?</h2>
    </div>
    <div class="qa-box__answer-box">
        <p class="qa-box__answer">При помощи встроенного метода .bind() можно привязать не только this, но и аргументы.</p>
        <pre>
            <code>
function mul(a, b) {
return a * b;
}

let double = mul.bind(null, 2);

double(3) // = mul(2, 3) = 6
double(4) // = mul(2, 4) = 8
double(5) // = mul(2, 5) = 10
            </code>
        </pre>
        <p class="qa-box__answer">В качестве this можно передать любой объект, но как правило это null.</p>
    </div>
</div>